Workbook
Name Lista_CafeDaManha: Ref_Alimentos!$L$2:$L$101
Name Lista_Almoco: Ref_Alimentos!$M$2:$M$101
Name Lista_Lanche: Ref_Alimentos!$N$2:$N$101
Name Lista_Jantar: Ref_Alimentos!$O$2:$O$101

Sheet Cuidados na Alimentação
A1: Cuidados na Alimentação — pós-infarto (25/08/2026)
A2: Seção | B2: Orientação
A3: Perfil de risco atual | B3: Homem, 48 anos, IAM em 25/08/2026 (3 procedimentos). Ecocardiograma de 29/09/2026: dentro da normalidade — FE 60% (Teichholz), sem alteração contrátil segmentar e função diastólica normal (o eco da internação, 26/08, mostrava FE 72% com hipocinesia segmentar leve; os dois valores de FE são normais, acima de 52%). Exames de 01/10/2026, já em uso contínuo dos remédios: LDL 47 (era 138 na internação), HDL 46 (era 34), triglicerídeos 70 (eram 343), colesterol total 108 (era 222) — perfil lipídico dentro das metas. Pontos ainda em aberto: HbA1c 5,9% (faixa de risco aumentado para diabetes) e função renal (creatinina 1,44, TFG 60, proteína na urina — ver 'Aviso pendente — função renal'). Placa carotídea leve (1–15%) já mostra aterosclerose além do evento agudo.
A4: Reduzir | B4: Gordura saturada e gordura trans (frituras, embutidos, carnes gordas, manteiga, produtos industrializados com 'gordura vegetal hidrogenada').
A5: Reduzir | B5: Açúcar e carboidrato refinado — prioridade alta: a HbA1c de 01/10/2026 foi 5,9%, na faixa de 'risco aumentado para diabetes' (5,7 a 6,4%), mesmo patamar de antes do infarto (6,0% em 2022, 5,9% em 2025). Os triglicerídeos normalizaram (343 → 70), mas manter o cuidado: refrigerante comum, doces, pão/arroz/massa branca em excesso.
A6: Reduzir | B6: Sódio — evitar sal em excesso, temperos prontos, embutidos, enlatados e fast-food; ler rótulo (mg de sódio por porção).
A7: Reduzir | B7: Álcool — evitar ou reduzir ao mínimo; álcool piora diretamente os triglicerídeos.
A8: Priorizar | B8: Fibras: grãos integrais, leguminosas (feijão, lentilha, grão-de-bico), vegetais e frutas variadas.
A9: Priorizar | B9: Ômega-3: peixes (preferir 2-3x/semana), azeite de oliva extra virgem, oleaginosas em pequena quantidade (castanhas, nozes).
A10: Priorizar | B10: Proteínas magras: frango sem pele, peixe, ovos, leguminosas; carnes vermelhas com moderação.
A11: Atenção especial — triglicerídeos e glicemia | B11: Triglicerídeos caíram de 343 mg/dL (internação) para 70 mg/dL (01/10/2026) — normal. Esse resultado vem da combinação remédio + dieta, então a orientação continua a mesma para não perdê-lo. Agora o motivo principal para segurar açúcar e carboidrato refinado é a glicemia: HbA1c 5,9% (risco aumentado para diabetes; glicose de jejum 92, normal). Continuar evitando refrigerante comum, suco industrializado e doces, e bebida alcoólica quase por completo (também por causa da dupla antiagregação). Perguntar ao médico se ele considera pré-diabetes e quando repetir a HbA1c.
A12: Atenção especial — LDL | B12: Resultado de 01/10/2026: LDL 47 mg/dL (era 138 na internação), já em uso de Rosucor + Ezetimiba. A meta pós-IAM varia por diretriz: <50 mg/dL (SBC, risco muito alto — a tabela de metas do próprio laudo segue a diretriz SBC 2025) e <55 mg/dL (ESC/EAS 2019, risco muito alto) — as duas já atingidas. Só estaria acima da meta se o médico usar <40 mg/dL, da categoria 'risco extremo' da SBC 2025 (exige critérios adicionais) — pergunte ao médico qual meta ele está usando. A combinação estatina (Rosucor) + Ezetimiba já prescrita é sustentada pelo estudo IMPROVE-IT (LDL médio de 53,7 mg/dL com a combinação, vs. 69,5 mg/dL só com estatina, e menos eventos cardiovasculares). Fontes na aba 'Fontes e Referências'.
A13: Aviso pendente — função renal | B13: Exames de 01/10/2026 (cerca de 4 semanas após a alta): creatinina 1,44 mg/dL e TFG 60 — melhorou pouco em relação à alta (1,50 / 57), mas continua acima do seu valor de antes do infarto (1,05 em 2022, 1,12 em 2025). Ou seja, não se resolveu no prazo de 7-14 dias que a ESUR descreve para lesão renal por contraste. Parte dessa elevação pode ser efeito esperado do Enalapril (a diretriz ESC 2021 tolera alta de creatinina de até 50%), mas quem avalia é o médico. Ureia 61 mg/dL, acima da referência (17-48) — pode subir por causa do rim, de desidratação ou de consumo alto de proteína. A urina tipo I deu proteína + — primeiro sinal objetivo do que antes era só suspeita; o exame que confirma e quantifica é a relação albumina/creatinina urinária (ACR/RAC, padrão KDIGO), ainda não feito. A KDIGO só fala em doença renal crônica quando a alteração persiste por mais de 3 meses — por isso o reexame importa. Na internação, a queda de TFG para 57 preencheu o critério objetivo de Lesão Renal Aguda estágio 1 da KDIGO (fórmula aplicada aos números, não diagnóstico médico). Orientação: o plano continua SEM restrição renal formal (sódio/potássio/proteína), mas, por cautela, não exagerar em proteína — evitar suplementos tipo whey e dietas hiperproteicas — até o médico avaliar. Revisar esta aba assim que o médico se posicionar.
... A20: Leitura de rótulos | B20: Ao comprar um produto industrializado, olhar sempre: sódio por porção, açúcares totais/adicionados, e a lista de ingredientes procurando 'gordura hidrogenada' ou 'gordura trans'. Prefira produtos com menos ingredientes e sem açúcar adicionado.

Sheet Plano Geral - Restaurante
A1: Plano Geral — o que comer, inclusive fora de casa
A2: Seção | B2: Conteúdo
A3: Modelo de prato | B3: 1/2 do prato: vegetais e salada (à vontade, tempero simples com azeite/limão). 1/4 do prato: proteína magra grelhada/assada (peixe, frango sem pele, ovo, leguminosas). 1/4 do prato: carboidrato integral (arroz integral, batata-doce, mandioca, pão de forma integral) em porção moderada.
A4: O que pedir | B4: Grelhado, assado ou cozido — sem manteiga extra ou molho cremoso. Peça o molho à parte para controlar a quantidade. Troque frituras por grelhados/assados. Troque refrigerante comum por água ou refrigerante zero. Sobremesa só ocasional e em porção pequena (dividir com alguém, se possível).
A5: O que evitar | B5: Frituras (empanados, milanesas), molhos à base de creme de leite/manteiga, embutidos (bacon, linguiça), pratos 'à parmegiana' ou gratinados com muito queijo, refrigerante comum, sobremesas grandes ou muito açucaradas.
A6: Perguntas úteis ao garçom | B6: "Esse prato pode vir grelhado, sem manteiga extra?" · "O molho leva creme de leite ou manteiga?" · "Dá para trocar a guarnição (fritas/farofa) por salada ou legumes?" · "Tem opção de refrigerante zero ou água com gás?"
A7: Exemplos de pratos que funcionam | B7: Peixe grelhado + legumes salteados + arroz integral. Frango grelhado sem pele + salada variada. Prato de grãos/leguminosas (feijoada de grão-de-bico, saladas com lentilha) + vegetais. Omelete de claras/ovo com legumes + salada.
A8: Em festas/eventos | B8: Priorize proteína grelhada e salada primeiro, para 'preencher' o prato com opções seguras. Álcool: evitar ou limitar ao mínimo por causa dos triglicerídeos. Doces: só uma porção pequena, ocasionalmente.

Sheet Alimentos e Quantidades
A1: Alimentos e Quantidades — lista de referência
B2: Liberado | C2: Moderar | D2: Evitar | G2: Gostoso: preencha você mesmo (menu suspenso na coluna)
A3: Categoria | B3: Alimento | C3: Marca | D3: Porção | E3: Frequência | F3: Classificação | G3: Gostoso | H3: Observação
A4: Frutas
B5: Maçã fuji (com casca) | D5: 1 unidade | E5: 1x/dia | F5: Liberado | H5: Vale para maçã em geral, com casca (mais fibra) — Fuji é só um pouco mais doce que outras variedades, sem diferença relevante para o quadro do paciente.
B6: Banana | D6: 1 unidade | E6: 1x/dia | F6: Liberado
B7: Uva | D7: 200 g | E7: 1x/semana | F7: Moderar | H7: Mais açúcar que outras frutas
B8: Manga | D8: 200 g | E8: 1x/semana | F8: Moderar | G8: Bom | H8: Mais açúcar que outras frutas
B9: Abacate | D9: 2 colheres de sopa | E9: 1x/dia | F9: Liberado | H9: Gordura boa, mas calórico
B10: Toranja / grapefruit | D10: - | E10: evitar | F10: Evitar | H10: Interage com o Ticagrelor (estudo mostrou quase o dobro do nível do remédio no sangue); a bula diz que não é esperado ser clinicamente relevante p/ a maioria, mas orienta evitar — mais seguro evitar, já que você toma 2 antiagregantes. Ver aba Fontes e Referências.
A11: Grãos e Cereais
B12: Arroz integral | D12: 200 g (cozido) | E12: quase todo dia | F12: Liberado
B13: Arroz branco | D13: 200 g (cozido) | E13: 2x/semana | F13: Moderar | H13: Preferir integral no restante da semana
B14: Aveia integral em flocos | C14: Quaker | D14: 4 colheres de sopa (~30 g) | E14: 1x/dia | F14: Liberado | H14: Rótulo real: 110 kcal, 2,8 g de fibra (1,2 g de beta-glucana — a fibra solúvel que ajuda a reduzir o colesterol), sem açúcar adicionado, 0 mg de sódio.
B15: Pão de forma integral | D15: 2 fatias | E15: 1x/dia | F15: Liberado
B16: Pão francês integral (multigrãos) | C16: Mambo | D16: 1 unidade (~67 g) | E16: 1x/dia | F16: Liberado | H16: Rótulo real (porção 50 g/meia unidade): 120 kcal, 208 mg de sódio, 1,6 g de fibras, sem açúcar adicionado. Com centeio, gergelim e linhaça — boa fonte de fibra, mas sódio moderado como a maioria dos pães; contém glúten.
B17: Tortilha | C17: Rap10 | D17: 1 unidade (33 g) | E17: 3x/semana | F17: Moderar | H17: Rótulo real: a porção declarada no rótulo é 40 g (1 tortilha de 33 g + um pedaço), com 120 kcal, 170 mg de sódio, 1,6 g de gordura saturada e 1,2 g de fibras. Para 1 tortilha inteira (33 g), isso equivale a ~99 kcal, 140 mg de sódio, 1,3 g de gordura saturada, 1,0 g de fibra, 0 g de gordura trans e 0,2 g de açúcar adicionado. Comparando dentro desta planilha: 1 pão francês integral tem cerca do dobro do sódio (279 mg) — o ponto de atenção da tortilha é mais a gordura saturada (4,0 g/100 g, acima do típico de uma tortilha simples) do que o sódio. Contém glúten (triticale). Sugestão gerada por IA — confirmar com nutricionista/cardiologista.
B18: Granola zero açúcar | C18: Castanha do Bem | D18: 20 g (1 colher de sopa) | E18: 1x/dia | F18: Liberado | H18: Rótulo real (porção 20 g): 83 kcal, 2,8 g de gordura (0,9 g saturada), 12 g de carboidrato, 1,1 g de açúcar (zero adicionado, adoçada com esteviol), 3 g de proteína, 2 g de fibra e 19 mg de sódio. Feita com aveia, coco, amêndoa, castanha de caju, castanha do pará e uva-passa — sem açúcar refinado, mas é calórica (415 kcal/100 g) e tem gordura saturada das castanhas/coco: manter na porção indicada, sem repetir a colher. Contém glúten; rótulo declara conter lactose (apesar de não haver laticínio nos ingredientes — provavelmente contaminação cruzada declarada); pode conter amendoim, avelã, centeio, leite, macadâmia, nozes, ovos, pecã, soja e trigo.
B19: Granola zero açúcar | C19: Mãe Terra | D19: 20 g (1 colher de sopa) | E19: 1x/dia | F19: Liberado | H19: Rótulo real (a porção do rótulo é 40 g/½ xícara; valores abaixo recalculados para 20 g, para manter a mesma porção das demais granolas da planilha): ~91 kcal, 3,6 g de gordura (0,7 g saturada, 0 g trans), 12 g de carboidrato, 0,3 g de açúcar total e zero adicionado (adoçada com eritritol, maltitol e glicosídeos de esteviol — polióis, geralmente bem tolerados nessa quantidade), 2,2 g de proteína, 1,6 g de fibra, só 1,3 mg de sódio (praticamente sem sódio). Leva castanha-do-pará, castanha-de-caju, coco e óleo vegetal — por isso é calórica (455 kcal/100 g) mesmo sendo zero açúcar: manter a porção, sem repetir a colher. A gordura saturada, por outro lado, é baixa na porção (0,7 g) e menor que a da granola Castanha do Bem. Contém glúten (aveia, flocos de trigo); pode conter diversos alérgenos por contaminação cruzada (amendoim, leite, castanhas variadas, soja).
A20: Proteínas
B21: Peixe | D21: 150 g | E21: 3x/semana | F21: Liberado | H21: Fonte de ômega-3
B22: Sashimi de salmão | D22: 150 g (6-8 fatias) | E22: 1-2x/semana | F22: Liberado | H22: Peixe cru, sem arroz — mesma fonte de ômega-3 do peixe grelhado, conta na mesma cota semanal de peixe. Cuidado é só com o shoyu (molho de soja) do acompanhamento, rico em sódio: usar pouco. Sugestão gerada por IA — confirmar com nutricionista/cardiologista.
B23: Sushi de salmão | D23: 8-10 peças (nigiri/hossomaki) | E23: 1x/semana | F23: Moderar | H23: Além do peixe, leva arroz temperado com açúcar/vinagre — mais carboidrato e um pouco de açúcar adicionado que o sashimi puro. Evitar versões com tempurá, cream cheese ou molhos cremosos/apimentados (mais gordura, sódio e calorias); usar pouco shoyu (sódio). Sugestão gerada por IA — confirmar com nutricionista/cardiologista.
B24: Frango sem pele | D24: 150 g | E24: quase todo dia | F24: Liberado
B25: Carne vermelha magra | D25: 150 g | E25: 1x/semana | F25: Moderar | H25: Preferir cortes magros
B26: Ovo | D26: 1 unidade | E26: até 5x/semana | F26: Liberado
B27: Feijão / leguminosas | D27: 1 concha | E27: 1x/dia | F27: Liberado
B28: Kare (curry japonês) com lombo de porco | D28: 1 concha (150-200 g do preparo, sem contar o arroz) | E28: 1x/semana | F28: Moderar | H28: O tablete de curry (roux) pronto costuma ser rico em sódio e conter gordura saturada (geralmente óleo de palma) na sua composição, além de ser espessado com farinha de trigo — é o principal ponto de atenção do prato, não o lombo suíno (corte magro) nem os vegetais (batata, cenoura, cebola). Preferir marcas com menos sódio por porção, se o rótulo estiver disponível. Sugestão gerada por IA — confirmar com nutricionista/cardiologista.
A29: Laticínios
B30: Leite desnatado | D30: 200 ml | E30: 1x/dia | F30: Liberado
B31: Queijo branco frescal | D31: 30 g | E31: 3x/semana | F31: Liberado | H31: Tipo fresco (ex.: Minas frescal), sem cura/salga pesada — bem menos sódio e gordura que queijos curados. Sugestão gerada por IA — confirmar com nutricionista/cardiologista.
B32: Queijo frescal light | C32: Polenghi | D32: 30 g (1 fatia) | E32: 3x/semana | F32: Liberado | H32: Rótulo real: 41 kcal e 105 mg de sódio por porção (bem abaixo de queijos comuns), 1,5 g de gordura saturada, sem açúcar adicionado. Contém lactose; sem glúten; pode conter soja.
B33: Mussarela | D33: 30 g | E33: 2x/semana | F33: Moderar | H33: Mais gordura saturada e sódio que o queijo branco frescal; prefira o frescal no dia a dia. Sugestão gerada por IA — confirmar com nutricionista/cardiologista.
B34: Iogurte natural (desnatado, sem açúcar) | D34: 1 unidade | E34: 1x/dia | F34: Liberado | H34: Prefira sempre a versão sem açúcar adicionado
B35: Iogurte grego zero | C35: Vigor | D35: 90 g (1 pote) | E35: 1x/dia | F35: Liberado | H35: Rótulo real: 50 kcal, 6,8 g de proteína (bem mais que iogurte comum), 0,2 g de gordura, 51 mg de sódio, zero adição de açúcar/gordura, sem lactose. Contém edulcorantes (sucralose e ciclamato).
B36: Requeijão | D36: 1 colher de sopa (≈15 g) | E36: 2x/semana | F36: Moderar | H36: Rico em gordura saturada e sódio; prefira a versão light. Sugestão gerada por IA — confirmar com nutricionista/cardiologista.
B37: Cream cheese light | C37: Philadelphia | D37: 1 colher de sopa (30 g) | E37: 2x/semana | F37: Moderar | H37: Rótulo real (30 g): 63 kcal, 3,5 g de gordura saturada e 0,1 g de gordura trans (mesmo sendo 'light', é bastante gordura saturada para uma porção — quase 30% do limite diário recomendado num plano de 2000 kcal), 115 mg de sódio, 1,1 g de açúcar (sem açúcar adicionado). Ingredientes: leite integral, creme de leite, leite em pó desnatado, sal, fermento lático, espessantes (goma jataí, carragena), conservador sorbato de potássio (não é o mesmo que sal light/cloreto de potássio — sem interação com o Enalapril). Sugestão gerada por IA — confirmar com nutricionista/cardiologista.
A38: Bebidas
B39: Água | D39: à vontade | E39: todos os dias | F39: Liberado
B40: Refrigerante zero | D40: 200 ml | E40: 1x/dia | F40: Moderar | H40: Sugestão gerada por IA — confirmar com nutricionista/cardiologista
...

Sheet Montar Refeição
A1: Montar uma Refeição — escolha os alimentos de cada refeição
A2: Escolha o alimento no menu suspenso da coluna 'Alimento' — a lista já vem filtrada por refeição (por isso não aparece arroz/feijão no café da manhã, por exemplo) e com os alimentos Liberados primeiro. Categoria, Porção sugerida e Classificação preenchem sozinhas. 'Sugestão' mostra um alimento que costuma combinar bem com o item escolhido logo acima (é uma dica, não é obrigatório escolher). Se 'Conflito' mostrar '⚠ Conflito', evite reunir esses itens na mesma refeição.
A3: Legenda: | B3: Liberado | C3: Moderar | D3: Evitar | F3: ⚠ Conflito
A5: CAFÉ DA MANHÃ
A6: Nº | B6: Alimento | C6: Categoria | D6: Porção sugerida | E6: Quantidade a comer | F6: Classificação | G6: Sugestão (com base no item anterior) | H6: Conflito
A7: 1 | C7: =IFERROR(INDEX(Ref_Alimentos!$B$2:$B$101,MATCH($B7,Ref_Alimentos!$A$2:$A$101,0)),"") | D7: =IFERROR(INDEX(Ref_Alimentos!$D$2:$D$101,MATCH($B7,Ref_Alimentos!$A$2:$A$101,0)),"") | F7: =IFERROR(INDEX(Ref_Alimentos!$C$2:$C$101,MATCH($B7,Ref_Alimentos!$A$2:$A$101,0)),"") | H7: =IF($B7="","",IF($F7="Evitar","⚠ Conflito",IF(AND($F7="Moderar",SUMPRODUCT(($B$7:$B$11<>"")*(ROW($B$7:$B$11)<>ROW($B7))*(($F$7:$F$11="Moderar")+($F$7:$F$11="Evitar")))>0),"⚠ Conflito","")))
A8: 2 | C8: =IFERROR(INDEX(Ref_Alimentos!$B$2:$B$101,MATCH($B8,Ref_Alimentos!$A$2:$A$101,0)),"") | D8: =IFERROR(INDEX(Ref_Alimentos!$D$2:$D$101,MATCH($B8,Ref_Alimentos!$A$2:$A$101,0)),"") | F8: =IFERROR(INDEX(Ref_Alimentos!$C$2:$C$101,MATCH($B8,Ref_Alimentos!$A$2:$A$101,0)),"") | G8: =IF($B7="","",IFERROR(INDEX(Ref_Alimentos!$R$2:$R$60,MATCH(IFERROR(INDEX(Ref_Alimentos!$U$2:$U$9,MATCH($C7,Ref_Alimentos!$T$2:$T$9,0)),"")&"|"&"Café da manhã",Ref_Alimentos!$Q$2:$Q$60,0)),"")) | H8: =IF($B8="","",IF($F8="Evitar","⚠ Conflito",IF(AND($F8="Moderar",SUMPRODUCT(($B$7:$B$11<>"")*(ROW($B$7:$B$11)<>ROW($B8))*(($F$7:$F$11="Moderar")+($F$7:$F$11="Evitar")))>0),"⚠ Conflito","")))
A9: 3 | C9: =IFERROR(INDEX(Ref_Alimentos!$B$2:$B$101,MATCH($B9,Ref_Alimentos!$A$2:$A$101,0)),"") | D9: =IFERROR(INDEX(Ref_Alimentos!$D$2:$D$101,MATCH($B9,Ref_Alimentos!$A$2:$A$101,0)),"") | F9: =IFERROR(INDEX(Ref_Alimentos!$C$2:$C$101,MATCH($B9,Ref_Alimentos!$A$2:$A$101,0)),"") | G9: =IF($B8="","",IFERROR(INDEX(Ref_Alimentos!$R$2:$R$60,MATCH(IFERROR(INDEX(Ref_Alimentos!$U$2:$U$9,MATCH($C8,Ref_Alimentos!$T$2:$T$9,0)),"")&"|"&"Café da manhã",Ref_Alimentos!$Q$2:$Q$60,0)),"")) | H9: =IF($B9="","",IF($F9="Evitar","⚠ Conflito",IF(AND($F9="Moderar",SUMPRODUCT(($B$7:$B$11<>"")*(ROW($B$7:$B$11)<>ROW($B9))*(($F$7:$F$11="Moderar")+($F$7:$F$11="Evitar")))>0),"⚠ Conflito","")))
A10: 4 | C10: =IFERROR(INDEX(Ref_Alimentos!$B$2:$B$101,MATCH($B10,Ref_Alimentos!$A$2:$A$101,0)),"") | D10: =IFERROR(INDEX(Ref_Alimentos!$D$2:$D$101,MATCH($B10,Ref_Alimentos!$A$2:$A$101,0)),"") | F10: =IFERROR(INDEX(Ref_Alimentos!$C$2:$C$101,MATCH($B10,Ref_Alimentos!$A$2:$A$101,0)),"") | G10: =IF($B9="","",IFERROR(INDEX(Ref_Alimentos!$R$2:$R$60,MATCH(IFERROR(INDEX(Ref_Alimentos!$U$2:$U$9,MATCH($C9,Ref_Alimentos!$T$2:$T$9,0)),"")&"|"&"Café da manhã",Ref_Alimentos!$Q$2:$Q$60,0)),"")) | H10: =IF($B10="","",IF($F10="Evitar","⚠ Conflito",IF(AND($F10="Moderar",SUMPRODUCT(($B$7:$B$11<>"")*(ROW($B$7:$B$11)<>ROW($B10))*(($F$7:$F$11="Moderar")+($F$7:$F$11="Evitar")))>0),"⚠ Conflito","")))
A11: 5 | C11: =IFERROR(INDEX(Ref_Alimentos!$B$2:$B$101,MATCH($B11,Ref_Alimentos!$A$2:$A$101,0)),"") | D11: =IFERROR(INDEX(Ref_Alimentos!$D$2:$D$101,MATCH($B11,Ref_Alimentos!$A$2:$A$101,0)),"") | F11: =IFERROR(INDEX(Ref_Alimentos!$C$2:$C$101,MATCH($B11,Ref_Alimentos!$A$2:$A$101,0)),"") | G11: =IF($B10="","",IFERROR(INDEX(Ref_Alimentos!$R$2:$R$60,MATCH(IFERROR(INDEX(Ref_Alimentos!$U$2:$U$9,MATCH($C10,Ref_Alimentos!$T$2:$T$9,0)),"")&"|"&"Café da manhã",Ref_Alimentos!$Q$2:$Q$60,0)),"")) | H11: =IF($B11="","",IF($F11="Evitar","⚠ Conflito",IF(AND($F11="Moderar",SUMPRODUCT(($B$7:$B$11<>"")*(ROW($B$7:$B$11)<>ROW($B11))*(($F$7:$F$11="Moderar")+($F$7:$F$11="Evitar")))>0),"⚠ Conflito","")))
A13: ALMOÇO
A14: Nº | B14: Alimento | C14: Categoria | D14: Porção sugerida | E14: Quantidade a comer | F14: Classificação | G14: Sugestão (com base no item anterior) | H14: Conflito
A15: 1 | C15: =IFERROR(INDEX(Ref_Alimentos!$B$2:$B$101,MATCH($B15,Ref_Alimentos!$A$2:$A$101,0)),"") | D15: =IFERROR(INDEX(Ref_Alimentos!$D$2:$D$101,MATCH($B15,Ref_Alimentos!$A$2:$A$101,0)),"") | F15: =IFERROR(INDEX(Ref_Alimentos!$C$2:$C$101,MATCH($B15,Ref_Alimentos!$A$2:$A$101,0)),"") | H15: =IF($B15="","",IF($F15="Evitar","⚠ Conflito",IF(AND($F15="Moderar",SUMPRODUCT(($B$15:$B$19<>"")*(ROW($B$15:$B$19)<>ROW($B15))*(($F$15:$F$19="Moderar")+($F$15:$F$19="Evitar")))>0),"⚠ Conflito","")))
A16: 2 | C16: =IFERROR(INDEX(Ref_Alimentos!$B$2:$B$101,MATCH($B16,Ref_Alimentos!$A$2:$A$101,0)),"") | D16: =IFERROR(INDEX(Ref_Alimentos!$D$2:$D$101,MATCH($B16,Ref_Alimentos!$A$2:$A$101,0)),"") | F16: =IFERROR(INDEX(Ref_Alimentos!$C$2:$C$101,MATCH($B16,Ref_Alimentos!$A$2:$A$101,0)),"") | G16: =IF($B15="","",IFERROR(INDEX(Ref_Alimentos!$R$2:$R$60,MATCH(IFERROR(INDEX(Ref_Alimentos!$U$2:$U$9,MATCH($C15,Ref_Alimentos!$T$2:$T$9,0)),"")&"|"&"Almoço",Ref_Alimentos!$Q$2:$Q$60,0)),"")) | H16: =IF($B16="","",IF($F16="Evitar","⚠ Conflito",IF(AND($F16="Moderar",SUMPRODUCT(($B$15:$B$19<>"")*(ROW($B$15:$B$19)<>ROW($B16))*(($F$15:$F$19="Moderar")+($F$15:$F$19="Evitar")))>0),"⚠ Conflito","")))
A17: 3 | C17: =IFERROR(INDEX(Ref_Alimentos!$B$2:$B$101,MATCH($B17,Ref_Alimentos!$A$2:$A$101,0)),"") | D17: =IFERROR(INDEX(Ref_Alimentos!$D$2:$D$101,MATCH($B17,Ref_Alimentos!$A$2:$A$101,0)),"") | F17: =IFERROR(INDEX(Ref_Alimentos!$C$2:$C$101,MATCH($B17,Ref_Alimentos!$A$2:$A$101,0)),"") | G17: =IF($B16="","",IFERROR(INDEX(Ref_Alimentos!$R$2:$R$60,MATCH(IFERROR(INDEX(Ref_Alimentos!$U$2:$U$9,MATCH($C16,Ref_Alimentos!$T$2:$T$9,0)),"")&"|"&"Almoço",Ref_Alimentos!$Q$2:$Q$60,0)),"")) | H17: =IF($B17="","",IF($F17="Evitar","⚠ Conflito",IF(AND($F17="Moderar",SUMPRODUCT(($B$15:$B$19<>"")*(ROW($B$15:$B$19)<>ROW($B17))*(($F$15:$F$19="Moderar")+($F$15:$F$19="Evitar")))>0),"⚠ Conflito","")))
A18: 4 | C18: =IFERROR(INDEX(Ref_Alimentos!$B$2:$B$101,MATCH($B18,Ref_Alimentos!$A$2:$A$101,0)),"") | D18: =IFERROR(INDEX(Ref_Alimentos!$D$2:$D$101,MATCH($B18,Ref_Alimentos!$A$2:$A$101,0)),"") | F18: =IFERROR(INDEX(Ref_Alimentos!$C$2:$C$101,MATCH($B18,Ref_Alimentos!$A$2:$A$101,0)),"") | G18: =IF($B17="","",IFERROR(INDEX(Ref_Alimentos!$R$2:$R$60,MATCH(IFERROR(INDEX(Ref_Alimentos!$U$2:$U$9,MATCH($C17,Ref_Alimentos!$T$2:$T$9,0)),"")&"|"&"Almoço",Ref_Alimentos!$Q$2:$Q$60,0)),"")) | H18: =IF($B18="","",IF($F18="Evitar","⚠ Conflito",IF(AND($F18="Moderar",SUMPRODUCT(($B$15:$B$19<>"")*(ROW($B$15:$B$19)<>ROW($B18))*(($F$15:$F$19="Moderar")+($F$15:$F$19="Evitar")))>0),"⚠ Conflito","")))
A19: 5 | C19: =IFERROR(INDEX(Ref_Alimentos!$B$2:$B$101,MATCH($B19,Ref_Alimentos!$A$2:$A$101,0)),"") | D19: =IFERROR(INDEX(Ref_Alimentos!$D$2:$D$101,MATCH($B19,Ref_Alimentos!$A$2:$A$101,0)),"") | F19: =IFERROR(INDEX(Ref_Alimentos!$C$2:$C$101,MATCH($B19,Ref_Alimentos!$A$2:$A$101,0)),"") | G19: =IF($B18="","",IFERROR(INDEX(Ref_Alimentos!$R$2:$R$60,MATCH(IFERROR(INDEX(Ref_Alimentos!$U$2:$U$9,MATCH($C18,Ref_Alimentos!$T$2:$T$9,0)),"")&"|"&"Almoço",Ref_Alimentos!$Q$2:$Q$60,0)),"")) | H19: =IF($B19="","",IF($F19="Evitar","⚠ Conflito",IF(AND($F19="Moderar",SUMPRODUCT(($B$15:$B$19<>"")*(ROW($B$15:$B$19)<>ROW($B19))*(($F$15:$F$19="Moderar")+($F$15:$F$19="Evitar")))>0),"⚠ Conflito","")))
A21: LANCHE
A22: Nº | B22: Alimento | C22: Categoria | D22: Porção sugerida | E22: Quantidade a comer | F22: Classificação | G22: Sugestão (com base no item anterior) | H22: Conflito
A23: 1 | C23: =IFERROR(INDEX(Ref_Alimentos!$B$2:$B$101,MATCH($B23,Ref_Alimentos!$A$2:$A$101,0)),"") | D23: =IFERROR(INDEX(Ref_Alimentos!$D$2:$D$101,MATCH($B23,Ref_Alimentos!$A$2:$A$101,0)),"") | F23: =IFERROR(INDEX(Ref_Alimentos!$C$2:$C$101,MATCH($B23,Ref_Alimentos!$A$2:$A$101,0)),"") | H23: =IF($B23="","",IF($F23="Evitar","⚠ Conflito",IF(AND($F23="Moderar",SUMPRODUCT(($B$23:$B$27<>"")*(ROW($B$23:$B$27)<>ROW($B23))*(($F$23:$F$27="Moderar")+($F$23:$F$27="Evitar")))>0),"⚠ Conflito","")))
A24: 2 | C24: =IFERROR(INDEX(Ref_Alimentos!$B$2:$B$101,MATCH($B24,Ref_Alimentos!$A$2:$A$101,0)),"") | D24: =IFERROR(INDEX(Ref_Alimentos!$D$2:$D$101,MATCH($B24,Ref_Alimentos!$A$2:$A$101,0)),"") | F24: =IFERROR(INDEX(Ref_Alimentos!$C$2:$C$101,MATCH($B24,Ref_Alimentos!$A$2:$A$101,0)),"") | G24: =IF($B23="","",IFERROR(INDEX(Ref_Alimentos!$R$2:$R$60,MATCH(IFERROR(INDEX(Ref_Alimentos!$U$2:$U$9,MATCH($C23,Ref_Alimentos!$T$2:$T$9,0)),"")&"|"&"Lanche",Ref_Alimentos!$Q$2:$Q$60,0)),"")) | H24: =IF($B24="","",IF($F24="Evitar","⚠ Conflito",IF(AND($F24="Moderar",SUMPRODUCT(($B$23:$B$27<>"")*(ROW($B$23:$B$27)<>ROW($B24))*(($F$23:$F$27="Moderar")+($F$23:$F$27="Evitar")))>0),"⚠ Conflito","")))
A25: 3 | C25: =IFERROR(INDEX(Ref_Alimentos!$B$2:$B$101,MATCH($B25,Ref_Alimentos!$A$2:$A$101,0)),"") | D25: =IFERROR(INDEX(Ref_Alimentos!$D$2:$D$101,MATCH($B25,Ref_Alimentos!$A$2:$A$101,0)),"") | F25: =IFERROR(INDEX(Ref_Alimentos!$C$2:$C$101,MATCH($B25,Ref_Alimentos!$A$2:$A$101,0)),"") | G25: =IF($B24="","",IFERROR(INDEX(Ref_Alimentos!$R$2:$R$60,MATCH(IFERROR(INDEX(Ref_Alimentos!$U$2:$U$9,MATCH($C24,Ref_Alimentos!$T$2:$T$9,0)),"")&"|"&"Lanche",Ref_Alimentos!$Q$2:$Q$60,0)),"")) | H25: =IF($B25="","",IF($F25="Evitar","⚠ Conflito",IF(AND($F25="Moderar",SUMPRODUCT(($B$23:$B$27<>"")*(ROW($B$23:$B$27)<>ROW($B25))*(($F$23:$F$27="Moderar")+($F$23:$F$27="Evitar")))>0),"⚠ Conflito","")))
A26: 4 | C26: =IFERROR(INDEX(Ref_Alimentos!$B$2:$B$101,MATCH($B26,Ref_Alimentos!$A$2:$A$101,0)),"") | D26: =IFERROR(INDEX(Ref_Alimentos!$D$2:$D$101,MATCH($B26,Ref_Alimentos!$A$2:$A$101,0)),"") | F26: =IFERROR(INDEX(Ref_Alimentos!$C$2:$C$101,MATCH($B26,Ref_Alimentos!$A$2:$A$101,0)),"") | G26: =IF($B25="","",IFERROR(INDEX(Ref_Alimentos!$R$2:$R$60,MATCH(IFERROR(INDEX(Ref_Alimentos!$U$2:$U$9,MATCH($C25,Ref_Alimentos!$T$2:$T$9,0)),"")&"|"&"Lanche",Ref_Alimentos!$Q$2:$Q$60,0)),"")) | H26: =IF($B26="","",IF($F26="Evitar","⚠ Conflito",IF(AND($F26="Moderar",SUMPRODUCT(($B$23:$B$27<>"")*(ROW($B$23:$B$27)<>ROW($B26))*(($F$23:$F$27="Moderar")+($F$23:$F$27="Evitar")))>0),"⚠ Conflito","")))
A27: 5 | C27: =IFERROR(INDEX(Ref_Alimentos!$B$2:$B$101,MATCH($B27,Ref_Alimentos!$A$2:$A$101,0)),"") | D27: =IFERROR(INDEX(Ref_Alimentos!$D$2:$D$101,MATCH($B27,Ref_Alimentos!$A$2:$A$101,0)),"") | F27: =IFERROR(INDEX(Ref_Alimentos!$C$2:$C$101,MATCH($B27,Ref_Alimentos!$A$2:$A$101,0)),"") | G27: =IF($B26="","",IFERROR(INDEX(Ref_Alimentos!$R$2:$R$60,MATCH(IFERROR(INDEX(Ref_Alimentos!$U$2:$U$9,MATCH($C26,Ref_Alimentos!$T$2:$T$9,0)),"")&"|"&"Lanche",Ref_Alimentos!$Q$2:$Q$60,0)),"")) | H27: =IF($B27="","",IF($F27="Evitar","⚠ Conflito",IF(AND($F27="Moderar",SUMPRODUCT(($B$23:$B$27<>"")*(ROW($B$23:$B$27)<>ROW($B27))*(($F$23:$F$27="Moderar")+($F$23:$F$27="Evitar")))>0),"⚠ Conflito","")))
A29: JANTAR
A30: Nº | B30: Alimento | C30: Categoria | D30: Porção sugerida | E30: Quantidade a comer | F30: Classificação | G30: Sugestão (com base no item anterior) | H30: Conflito
A31: 1 | C31: =IFERROR(INDEX(Ref_Alimentos!$B$2:$B$101,MATCH($B31,Ref_Alimentos!$A$2:$A$101,0)),"") | D31: =IFERROR(INDEX(Ref_Alimentos!$D$2:$D$101,MATCH($B31,Ref_Alimentos!$A$2:$A$101,0)),"") | F31: =IFERROR(INDEX(Ref_Alimentos!$C$2:$C$101,MATCH($B31,Ref_Alimentos!$A$2:$A$101,0)),"") | H31: =IF($B31="","",IF($F31="Evitar","⚠ Conflito",IF(AND($F31="Moderar",SUMPRODUCT(($B$31:$B$35<>"")*(ROW($B$31:$B$35)<>ROW($B31))*(($F$31:$F$35="Moderar")+($F$31:$F$35="Evitar")))>0),"⚠ Conflito","")))
A32: 2 | C32: =IFERROR(INDEX(Ref_Alimentos!$B$2:$B$101,MATCH($B32,Ref_Alimentos!$A$2:$A$101,0)),"") | D32: =IFERROR(INDEX(Ref_Alimentos!$D$2:$D$101,MATCH($B32,Ref_Alimentos!$A$2:$A$101,0)),"") | F32: =IFERROR(INDEX(Ref_Alimentos!$C$2:$C$101,MATCH($B32,Ref_Alimentos!$A$2:$A$101,0)),"") | G32: =IF($B31="","",IFERROR(INDEX(Ref_Alimentos!$R$2:$R$60,MATCH(IFERROR(INDEX(Ref_Alimentos!$U$2:$U$9,MATCH($C31,Ref_Alimentos!$T$2:$T$9,0)),"")&"|"&"Jantar",Ref_Alimentos!$Q$2:$Q$60,0)),"")) | H32: =IF($B32="","",IF($F32="Evitar","⚠ Conflito",IF(AND($F32="Moderar",SUMPRODUCT(($B$31:$B$35<>"")*(ROW($B$31:$B$35)<>ROW($B32))*(($F$31:$F$35="Moderar")+($F$31:$F$35="Evitar")))>0),"⚠ Conflito","")))
A33: 3 | C33: =IFERROR(INDEX(Ref_Alimentos!$B$2:$B$101,MATCH($B33,Ref_Alimentos!$A$2:$A$101,0)),"") | D33: =IFERROR(INDEX(Ref_Alimentos!$D$2:$D$101,MATCH($B33,Ref_Alimentos!$A$2:$A$101,0)),"") | F33: =IFERROR(INDEX(Ref_Alimentos!$C$2:$C$101,MATCH($B33,Ref_Alimentos!$A$2:$A$101,0)),"") | G33: =IF($B32="","",IFERROR(INDEX(Ref_Alimentos!$R$2:$R$60,MATCH(IFERROR(INDEX(Ref_Alimentos!$U$2:$U$9,MATCH($C32,Ref_Alimentos!$T$2:$T$9,0)),"")&"|"&"Jantar",Ref_Alimentos!$Q$2:$Q$60,0)),"")) | H33: =IF($B33="","",IF($F33="Evitar","⚠ Conflito",IF(AND($F33="Moderar",SUMPRODUCT(($B$31:$B$35<>"")*(ROW($B$31:$B$35)<>ROW($B33))*(($F$31:$F$35="Moderar")+($F$31:$F$35="Evitar")))>0),"⚠ Conflito","")))
A34: 4 | C34: =IFERROR(INDEX(Ref_Alimentos!$B$2:$B$101,MATCH($B34,Ref_Alimentos!$A$2:$A$101,0)),"") | D34: =IFERROR(INDEX(Ref_Alimentos!$D$2:$D$101,MATCH($B34,Ref_Alimentos!$A$2:$A$101,0)),"") | F34: =IFERROR(INDEX(Ref_Alimentos!$C$2:$C$101,MATCH($B34,Ref_Alimentos!$A$2:$A$101,0)),"") | G34: =IF($B33="","",IFERROR(INDEX(Ref_Alimentos!$R$2:$R$60,MATCH(IFERROR(INDEX(Ref_Alimentos!$U$2:$U$9,MATCH($C33,Ref_Alimentos!$T$2:$T$9,0)),"")&"|"&"Jantar",Ref_Alimentos!$Q$2:$Q$60,0)),"")) | H34: =IF($B34="","",IF($F34="Evitar","⚠ Conflito",IF(AND($F34="Moderar",SUMPRODUCT(($B$31:$B$35<>"")*(ROW($B$31:$B$35)<>ROW($B34))*(($F$31:$F$35="Moderar")+($F$31:$F$35="Evitar")))>0),"⚠ Conflito","")))
A35: 5 | C35: =IFERROR(INDEX(Ref_Alimentos!$B$2:$B$101,MATCH($B35,Ref_Alimentos!$A$2:$A$101,0)),"") | D35: =IFERROR(INDEX(Ref_Alimentos!$D$2:$D$101,MATCH($B35,Ref_Alimentos!$A$2:$A$101,0)),"") | F35: =IFERROR(INDEX(Ref_Alimentos!$C$2:$C$101,MATCH($B35,Ref_Alimentos!$A$2:$A$101,0)),"") | G35: =IF($B34="","",IFERROR(INDEX(Ref_Alimentos!$R$2:$R$60,MATCH(IFERROR(INDEX(Ref_Alimentos!$U$2:$U$9,MATCH($C34,Ref_Alimentos!$T$2:$T$9,0)),"")&"|"&"Jantar",Ref_Alimentos!$Q$2:$Q$60,0)),"")) | H35: =IF($B35="","",IF($F35="Evitar","⚠ Conflito",IF(AND($F35="Moderar",SUMPRODUCT(($B$31:$B$35<>"")*(ROW($B$31:$B$35)<>ROW($B35))*(($F$31:$F$35="Moderar")+($F$31:$F$35="Evitar")))>0),"⚠ Conflito","")))
A37: Limitações conhecidas: a ordem do menu suspenso é fixa (Liberado > Moderar > Evitar), ela não se reordena sozinha conforme o item anterior — quem indica o que combina melhor é a coluna 'Sugestão'. A coluna 'Conflito' é uma aproximação (marca um item 'Evitar' sozinho, ou dois itens 'Moderar'/'Evitar' juntos na mesma refeição) — não é uma checagem real de interação entre os dois alimentos específicos.

Sheet Fontes e Referências
A1: Fontes e Referências — de onde vieram as informações médicas
A2: Pesquisa feita em 04/09/2026, priorizando bulas oficiais (Anvisa), estudos revisados por pares (PubMed/PMC), órgãos de saúde do governo (NIH) e diretrizes de sociedades médicas (SBC, AHA, ACC/ESC, KDIGO, ESUR, ESVS, ADA/SBD). A coluna 'Área' diz se a fonte é sobre alimentação/interação com alimento ou sobre o quadro clínico em geral. Nenhuma destas fontes substitui a avaliação do seu médico — use como ponto de partida para perguntar e confirmar na consulta. Clique no link da coluna 'Fonte' para abrir a página original.
A3: Nº | B3: Afirmação que a fonte sustenta | C3: Fonte | D3: Tipo de fonte | E3: Área | F3: URL completa
A4: 1 | B4: Suco de toranja em quantidade alta quase dobra o nível de Ticagrelor no sangue e aumenta seu efeito antiagregante | C4: Holmberg et al., 2013, Br J Clin Pharmacol (PubMed) | D4: Estudo clínico revisado por pares | E4: Alimentação | F4: https://pubmed.ncbi.nlm.nih.gov/23126367/
A5: 2 | B5: Bula brasileira do Brilinta (Ticagrelor) cita esse estudo e orienta evitar suco de toranja em grande quantidade | C5: Bula profissional Brilinta, AstraZeneca do Brasil (aprovada pela Anvisa) | D5: Bula oficial (Anvisa) | E5: Alimentação | F5: https://www.azmed.com.br/content/dam/multibrand/br/pt/azmed-2022/home/bulas-profissionais/bulas/Brilinta_Bula_Profissional.pdf
A6: 3 | B6: Enalapril (IECA) + sal light/suplemento de potássio aumenta risco de hipercalemia | C6: StatPearls (NCBI Bookshelf), "Enalapril" | D6: Referência clínica revisada por pares | E6: Alimentação | F6: https://www.ncbi.nlm.nih.gov/books/NBK557708/
A7: 4 | B7: Álcool combinado com Aspirina aumenta o risco de sangramento gastrointestinal alto | C7: Kaufman et al., 1999, Ann Epidemiol (PubMed) | D7: Estudo epidemiológico revisado por pares | E7: Alimentação | F7: https://pubmed.ncbi.nlm.nih.gov/10566713/
A8: 5 | B8: Arroz de levedura vermelha (red yeast rice) pode causar os mesmos efeitos colaterais e interações de uma estatina | C8: NIH — National Center for Complementary and Integrative Health | D8: Órgão oficial do governo dos EUA (NIH) | E8: Alimentação | F8: https://www.nccih.nih.gov/health/red-yeast-rice
A9: 6 | B9: Rosuvastatina não tem interação relevante com toranja (via CYP2C9, diferente da via CYP3A4 usada pelo Ticagrelor) | C9: Bailey DG et al., 2013, CMAJ, "Grapefruit-medication interactions" | D9: Revisão científica revisada por pares | E9: Alimentação | F9: https://pmc.ncbi.nlm.nih.gov/articles/PMC3589309/
A10: 7 | B10: Duração de 12 meses de dupla antiagregação (Aspirina + Ticagrelor) após stent em síndrome coronariana aguda | C10: 2016 ACC/AHA Guideline Focused Update on DAPT; reafirmado na diretriz ACS 2025 (JACC) | D10: Diretriz de sociedades médicas (ACC/AHA) | E10: Alimentação | F10: https://www.acc.org/latest-in-cardiology/ten-points-to-remember/2016/03/25/14/56/2016-acc-aha-guideline-focused-update-on-dapt
A11: 8 | B11: Metas de LDL pós-infarto: <50 mg/dL (SBC, risco muito alto — já em 2017 e mantida em 2025, tabela usada no laudo do laboratório); <40 mg/dL na categoria "risco extremo" (SBC 2025, com critérios adicionais); <55 mg/dL (ESC/EAS 2019, risco muito alto) | C11: Diretriz Brasileira de Dislipidemias e Prevenção da Aterosclerose 2025 (SBC), Arq Bras Cardiol | D11: Diretriz de sociedade médica (SBC) | E11: Alimentação | F11: https://www.scielo.br/j/abc/a/tRJrwGzKX6C4GvMqdJpZcGk/?lang=pt
A12: 9 | B12: Diretriz alimentar cardioprotetora: sódio controlado, gordura saturada <6% das calorias, padrão Mediterrâneo/DASH | C12: American Heart Association — AHA Diet and Lifestyle Recommendations / 2026 Dietary Guidance to Improve Cardiovascular Health (Circulation) | D12: Diretriz de sociedade médica (AHA) | E12: Alimentação | F12: https://www.heart.org/en/healthy-living/healthy-eating/eat-smart/nutrition-basics/aha-diet-and-lifestyle-recommendations
A13: 10 | B13: No Brasil, a Dieta Cardioprotetora Brasileira (DICA Br) aplica essas mesmas recomendações a alimentos típicos brasileiros | C13: I Diretriz Brasileira de Prevenção Cardiovascular (SBC), Arq Bras Cardiol | D13: Diretriz de sociedade médica (SBC) | E13: Alimentação | F13: https://www.scielo.br/j/abc/a/X94tMKwdnBjkCzVKpXwBqmD/?lang=pt
A14: 11 | B14: Critério objetivo de Lesão Renal Aguda (LRA) estágio 1: creatinina sobe ≥0,3 mg/dL em 48h | C14: KDIGO — Clinical Practice Guideline for Acute Kidney Injury, 2012 | D14: Diretriz de sociedade médica (KDIGO) | E14: Clínico geral | F14: https://kdigo.org/wp-content/uploads/2016/10/KDIGO-2012-AKI-Guideline-English.pdf
A15: 12 | B15: Exame padrão para proteinúria é a relação albumina/creatinina urinária (ACR/RAC), categorias A1/A2/A3 | C15: KDIGO — Clinical Practice Guideline for CKD, 2012 (categorias mantidas na atualização 2024) | D15: Diretriz de sociedade médica (KDIGO) | E15: Clínico geral | F15: https://kdigo.org/wp-content/uploads/2017/02/KDIGO_2012_CKD_GL.pdf
... A25: 22 | B25: Mesma conduta conservadora para placa carotídea leve, do lado da prevenção de AVC | C25: AHA/ASA — Guideline for the Prevention of Stroke in Patients With Stroke and TIA, 2021 | D25: Diretriz de sociedade médica (AHA/ASA) | E25: Clínico geral | F25: https://www.ahajournals.org/doi/10.1161/STR.0000000000000375
A27: Lista completa com os mesmos links (mais fácil de clicar em Markdown) também em referencia/historico-tratamento.md, seção 'Referências médicas'.

Sheet Ref_Alimentos
A1: Alimento | B1: Categoria | C1: Classificação | D1: Porção | E1: Frequência | F1: Observação | G1: Café da manhã | H1: Almoço | I1: Lanche | J1: Jantar | L1: Lista — Café da manhã | M1: Lista — Almoço | N1: Lista — Lanche | O1: Lista — Jantar | Q1: Chave (Categoria|Refeição) | R1: Alimento em destaque | T1: Categoria escolhida | U1: Categoria sugerida
A2: Maçã fuji (com casca) | B2: Frutas | C2: Liberado | D2: 1 unidade | E2: 1x/dia | F2: Vale para maçã em geral, com casca (mais fibra) — Fuji é só um pouco mais doce que outras variedades, sem diferença relevante para o quadro do paciente. | G2: X | I2: X | L2: Maçã fuji (com casca) | M2: Arroz integral | N2: Maçã fuji (com casca) | O2: Arroz integral | Q2: Frutas|Café da manhã | R2: Maçã fuji (com casca) | T2: Laticínios | U2: Grãos e Cereais
A3: Banana | B3: Frutas | C3: Liberado | D3: 1 unidade | E3: 1x/dia | G3: X | I3: X | L3: Banana | M3: Peixe | N3: Banana | O3: Peixe | Q3: Grãos e Cereais|Café da manhã | R3: Aveia integral em flocos | T3: Grãos e Cereais | U3: Laticínios
A4: Uva | B4: Frutas | C4: Moderar | D4: 200 g | E4: 1x/semana | F4: Mais açúcar que outras frutas | G4: X | I4: X | L4: Abacate | M4: Sashimi de salmão | N4: Abacate | O4: Sashimi de salmão | Q4: Proteínas|Café da manhã | R4: Ovo | T4: Proteínas | U4: Vegetais e Verduras
A5: Manga | B5: Frutas | C5: Moderar | D5: 200 g | E5: 1x/semana | F5: Mais açúcar que outras frutas | G5: X | I5: X | L5: Aveia integral em flocos | M5: Frango sem pele | N5: Pão de forma integral | O5: Frango sem pele | Q5: Laticínios|Café da manhã | R5: Leite desnatado | T5: Vegetais e Verduras | U5: Proteínas
A6: Abacate | B6: Frutas | C6: Liberado | D6: 2 colheres de sopa | E6: 1x/dia | F6: Gordura boa, mas calórico | G6: X | I6: X | L6: Pão de forma integral | M6: Ovo | N6: Pão francês integral (multigrãos) | O6: Ovo | Q6: Bebidas|Café da manhã | R6: Água | T6: Bebidas | U6: Proteínas
A7: Toranja / grapefruit | B7: Frutas | C7: Evitar | D7: - | E7: evitar | F7: Interage com o Ticagrelor (estudo mostrou quase o dobro do nível do remédio no sangue); a bula diz que não é esperado ser clinicamente relevante p/ a maioria, mas orienta evitar — mais seguro evitar, já que você toma 2 antiagregantes. Ver aba Fontes e Referências. | G7: X | I7: X | L7: Pão francês integral (multigrãos) | M7: Feijão / leguminosas | N7: Granola zero açúcar | O7: Feijão / leguminosas | Q7: Doces e Sobremesas|Café da manhã | R7: Açúcar refinado | T7: Frutas | U7: Laticínios
A8: Arroz integral | B8: Grãos e Cereais | C8: Liberado | D8: 200 g (cozido) | E8: quase todo dia | H8: X | J8: X | L8: Granola zero açúcar | M8: Água | N8: Granola zero açúcar | O8: Água | Q8: Gorduras e Temperos|Café da manhã | R8: Creme de tahine | T8: Doces e Sobremesas | U8: Frutas
A9: Arroz branco | B9: Grãos e Cereais | C9: Moderar | D9: 200 g (cozido) | E9: 2x/semana | F9: Preferir integral no restante da semana | H9: X | J9: X | L9: Granola zero açúcar | M9: Azeite de oliva extra virgem | N9: Leite desnatado | O9: Azeite de oliva extra virgem | Q9: Vegetais e Verduras|Café da manhã | R9: Vegetais e verduras em geral | T9: Gorduras e Temperos | U9: Vegetais e Verduras
A10: Aveia integral em flocos | B10: Grãos e Cereais | C10: Liberado | D10: 4 colheres de sopa (~30 g) | E10: 1x/dia | F10: Rótulo real: 110 kcal, 2,8 g de fibra (1,2 g de beta-glucana — a fibra solúvel que ajuda a reduzir o colesterol), sem açúcar adicionado, 0 mg de sódio. | G10: X | L10: Ovo | M10: Creme de tahine | N10: Queijo branco frescal | O10: Creme de tahine | Q10: Grãos e Cereais|Almoço | R10: Arroz integral
A11: Pão de forma integral | B11: Grãos e Cereais | C11: Liberado | D11: 2 fatias | E11: 1x/dia | G11: X | I11: X | L11: Leite desnatado | M11: Ervas e temperos naturais | N11: Queijo frescal light | O11: Ervas e temperos naturais | Q11: Proteínas|Almoço | R11: Peixe
A12: Pão francês integral (multigrãos) | B12: Grãos e Cereais | C12: Liberado | D12: 1 unidade (~67 g) | E12: 1x/dia | F12: Rótulo real (porção 50 g/meia unidade): 120 kcal, 208 mg de sódio, 1,6 g de fibras, sem açúcar adicionado. Com centeio, gergelim e linhaça — boa fonte de fibra, mas sódio moderado como a maioria dos pães; contém glúten. | G12: X | I12: X | L12: Queijo branco frescal | M12: Vegetais e verduras em geral | N12: Iogurte natural (desnatado, sem açúcar) | O12: Vegetais e verduras em geral | Q12: Bebidas|Almoço | R12: Água
A13: Tortilha | B13: Grãos e Cereais | C13: Moderar | D13: 1 unidade (33 g) | E13: 3x/semana | F13: Rótulo real: a porção declarada no rótulo é 40 g (1 tortilha de 33 g + um pedaço), com 120 kcal, 170 mg de sódio, 1,6 g de gordura saturada e 1,2 g de fibras. Para 1 tortilha inteira (33 g), isso equivale a ~99 kcal, 140 mg de sódio, 1,3 g de gordura saturada, 1,0 g de fibra, 0 g de gordura trans e 0,2 g de açúcar adicionado. Comparando dentro desta planilha: 1 pão francês integral tem cerca do dobro do sódio (279 mg) — o ponto de atenção da tortilha é mais a gordura saturada (4,0 g/100 g, acima do típico de uma tortilha simples) do que o sódio. Contém glúten (triticale). Sugestão gerada por IA — confirmar com nutricionista/cardiologista. | G13: X | H13: X | I13: X | J13: X | L13: Queijo frescal light | M13: Brócolis | N13: Iogurte grego zero | O13: Brócolis | Q13: Doces e Sobremesas|Almoço | R13: Açúcar refinado
A14: Granola zero açúcar | B14: Grãos e Cereais | C14: Liberado | D14: 20 g (1 colher de sopa) | E14: 1x/dia | F14: Rótulo real (porção 20 g): 83 kcal, 2,8 g de gordura (0,9 g saturada), 12 g de carboidrato, 1,1 g de açúcar (zero adicionado, adoçada com esteviol), 3 g de proteína, 2 g de fibra e 19 mg de sódio. Feita com aveia, coco, amêndoa, castanha de caju, castanha do pará e uva-passa — sem açúcar refinado, mas é calórica (415 kcal/100 g) e tem gordura saturada das castanhas/coco: manter na porção indicada, sem repetir a colher. Contém glúten; rótulo declara conter lactose (apesar de não haver laticínio nos ingredientes — provavelmente contaminação cruzada declarada); pode conter amendoim, avelã, centeio, leite, macadâmia, nozes, ovos, pecã, soja e trigo. | G14: X | I14: X | L14: Iogurte natural (desnatado, sem açúcar) | M14: Couve | N14: Água | O14: Couve | Q14: Gorduras e Temperos|Almoço | R14: Azeite de oliva extra virgem
A15: Granola zero açúcar | B15: Grãos e Cereais | C15: Liberado | D15: 20 g (1 colher de sopa) | E15: 1x/dia | F15: Rótulo real (a porção do rótulo é 40 g/½ xícara; valores abaixo recalculados para 20 g, para manter a mesma porção das demais granolas da planilha): ~91 kcal, 3,6 g de gordura (0,7 g saturada, 0 g trans), 12 g de carboidrato, 0,3 g de açúcar total e zero adicionado (adoçada com eritritol, maltitol e glicosídeos de esteviol — polióis, geralmente bem tolerados nessa quantidade), 2,2 g de proteína, 1,6 g de fibra, só 1,3 mg de sódio (praticamente sem sódio). Leva castanha-do-pará, castanha-de-caju, coco e óleo vegetal — por isso é calórica (455 kcal/100 g) mesmo sendo zero açúcar: manter a porção, sem repetir a colher. A gordura saturada, por outro lado, é baixa na porção (0,7 g) e menor que a da granola Castanha do Bem. Contém glúten (aveia, flocos de trigo); pode conter diversos alérgenos por contaminação cruzada (amendoim, leite, castanhas variadas, soja). | G15: X | I15: X | L15: Iogurte grego zero | M15: Espinafre | N15: Café sem açúcar | O15: Espinafre | Q15: Vegetais e Verduras|Almoço | R15: Vegetais e verduras em geral
A16: Peixe | B16: Proteínas | C16: Liberado | D16: 150 g | E16: 3x/semana | F16: Fonte de ômega-3 | H16: X | J16: X | L16: Água | M16: Tomate | N16: Creme de tahine | O16: Tomate | Q16: Frutas|Lanche | R16: Maçã fuji (com casca)
A17: Sashimi de salmão | B17: Proteínas | C17: Liberado | D17: 150 g (6-8 fatias) | E17: 1-2x/semana | F17: Peixe cru, sem arroz — mesma fonte de ômega-3 do peixe grelhado, conta na mesma cota semanal de peixe. Cuidado é só com o shoyu (molho de soja) do acompanhamento, rico em sódio: usar pouco. Sugestão gerada por IA — confirmar com nutricionista/cardiologista. | H17: X | J17: X | L17: Café sem açúcar | M17: Cenoura | N17: Vegetais e verduras em geral | O17: Cenoura | Q17: Grãos e Cereais|Lanche | R17: Pão de forma integral
A18: Sushi de salmão | B18: Proteínas | C18: Moderar | D18: 8-10 peças (nigiri/hossomaki) | E18: 1x/semana | F18: Além do peixe, leva arroz temperado com açúcar/vinagre — mais carboidrato e um pouco de açúcar adicionado que o sashimi puro. Evitar versões com tempurá, cream cheese ou molhos cremosos/apimentados (mais gordura, sódio e calorias); usar pouco shoyu (sódio). Sugestão gerada por IA — confirmar com nutricionista/cardiologista. | H18: X | J18: X | L18: Creme de tahine | M18: Abobrinha | N18: Tomate | O18: Abobrinha | Q18: Laticínios|Lanche | R18: Leite desnatado
A19: Frango sem pele | B19: Proteínas | C19: Liberado | D19: 150 g | E19: quase todo dia | H19: X | J19: X | L19: Vegetais e verduras em geral | M19: Beterraba | N19: Cenoura | O19: Beterraba | Q19: Bebidas|Lanche | R19: Água
A20: Carne vermelha magra | B20: Proteínas | C20: Moderar | D20: 150 g | E20: 1x/semana | F20: Preferir cortes magros | H20: X | J20: X | L20: Tomate | M20: Alface e folhas verdes (rúcula, agrião) | N20: Alface e folhas verdes (rúcula, agrião) | O20: Alface e folhas verdes (rúcula, agrião) | Q20: Doces e Sobremesas|Lanche | R20: Açúcar refinado
A21: Ovo | B21: Proteínas | C21: Liberado | D21: 1 unidade | E21: até 5x/semana | G21: X | H21: X | J21: X | L21: Uva | M21: Pepino | N21: Pepino | O21: Pepino | Q21: Gorduras e Temperos|Lanche | R21: Creme de tahine
A22: Feijão / leguminosas | B22: Proteínas | C22: Liberado | D22: 1 concha | E22: 1x/dia | H22: X | J22: X | L22: Manga | M22: Berinjela | N22: Pimentão | O22: Berinjela | Q22: Vegetais e Verduras|Lanche | R22: Vegetais e verduras em geral
A23: Kare (curry japonês) com lombo de porco | B23: Proteínas | C23: Moderar | D23: 1 concha (150-200 g do preparo, sem contar o arroz) | E23: 1x/semana | F23: O tablete de curry (roux) pronto costuma ser rico em sódio e conter gordura saturada (geralmente óleo de palma) na sua composição, além de ser espessado com farinha de trigo — é o principal ponto de atenção do prato, não o lombo suíno (corte magro) nem os vegetais (batata, cenoura, cebola). Preferir marcas com menos sódio por porção, se o rótulo estiver disponível. Sugestão gerada por IA — confirmar com nutricionista/cardiologista. | H23: X | J23: X | L23: Tortilha | M23: Pimentão | N23: Uva | O23: Pimentão | Q23: Grãos e Cereais|Jantar | R23: Arroz integral
A24: Leite desnatado | B24: Laticínios | C24: Liberado | D24: 200 ml | E24: 1x/dia | G24: X | I24: X | L24: Mussarela | M24: Repolho | N24: Manga | O24: Repolho | Q24: Proteínas|Jantar | R24: Peixe
A25: Queijo branco frescal | B25: Laticínios | C25: Liberado | D25: 30 g | E25: 3x/semana | F25: Tipo fresco (ex.: Minas frescal), sem cura/salga pesada — bem menos sódio e gordura que queijos curados. Sugestão gerada por IA — confirmar com nutricionista/cardiologista. | G25: X | I25: X | L25: Requeijão | M25: Arroz branco | N25: Tortilha | O25: Arroz branco | Q25: Bebidas|Jantar | R25: Água
A26: Queijo frescal light | B26: Laticínios | C26: Liberado | D26: 30 g (1 fatia) | E26: 3x/semana | F26: Rótulo real: 41 kcal e 105 mg de sódio por porção (bem abaixo de queijos comuns), 1,5 g de gordura saturada, sem açúcar adicionado. Contém lactose; sem glúten; pode conter soja. | G26: X | I26: X | L26: Cream cheese light | M26: Tortilha | N26: Mussarela | O26: Tortilha | Q26: Doces e Sobremesas|Jantar | R26: Açúcar refinado
A27: Mussarela | B27: Laticínios | C27: Moderar | D27: 30 g | E27: 2x/semana | F27: Mais gordura saturada e sódio que o queijo branco frescal; prefira o frescal no dia a dia. Sugestão gerada por IA — confirmar com nutricionista/cardiologista. | G27: X | I27: X | L27: Suco natural sem açúcar | M27: Sushi de salmão | N27: Requeijão | O27: Sushi de salmão | Q27: Gorduras e Temperos|Jantar | R27: Azeite de oliva extra virgem
A28: Iogurte natural (desnatado, sem açúcar) | B28: Laticínios | C28: Liberado | D28: 1 unidade | E28: 1x/dia | F28: Prefira sempre a versão sem açúcar adicionado | G28: X | I28: X | L28: Toranja / grapefruit | M28: Carne vermelha magra | N28: Cream cheese light | O28: Carne vermelha magra | Q28: Vegetais e Verduras|Jantar | R28: Vegetais e verduras em geral
A29: Iogurte grego zero | B29: Laticínios | C29: Liberado | D29: 90 g (1 pote) | E29: 1x/dia | F29: Rótulo real: 50 kcal, 6,8 g de proteína (bem mais que iogurte comum), 0,2 g de gordura, 51 mg de sódio, zero adição de açúcar/gordura, sem lactose. Contém edulcorantes (sucralose e ciclamato). | G29: X | I29: X | L29: Suco de toranja / grapefruit | M29: Kare (curry japonês) com lombo de porco | N29: Refrigerante zero | O29: Kare (curry japonês) com lombo de porco
A30: Requeijão | B30: Laticínios | C30: Moderar | D30: 1 colher de sopa (≈15 g) | E30: 2x/semana | F30: Rico em gordura saturada e sódio; prefira a versão light. Sugestão gerada por IA — confirmar com nutricionista/cardiologista. | G30: X | I30: X | L30: Açúcar refinado | M30: Refrigerante zero | N30: Suco natural sem açúcar | O30: Refrigerante zero
A31: Cream cheese light | B31: Laticínios | C31: Moderar | D31: 1 colher de sopa (30 g) | E31: 2x/semana | F31: Rótulo real (30 g): 63 kcal, 3,5 g de gordura saturada e 0,1 g de gordura trans (mesmo sendo 'light', é bastante gordura saturada para uma porção — quase 30% do limite diário recomendado num plano de 2000 kcal), 115 mg de sódio, 1,1 g de açúcar (sem açúcar adicionado). Ingredientes: leite integral, creme de leite, leite em pó desnatado, sal, fermento lático, espessantes (goma jataí, carragena), conservador sorbato de potássio (não é o mesmo que sal light/cloreto de potássio — sem interação com o Enalapril). Sugestão gerada por IA — confirmar com nutricionista/cardiologista. | G31: X | I31: X | L31: Manteiga | M31: Sal | N31: Chocolate amargo (70%+) | O31: Sal
A32: Água | B32: Bebidas | C32: Liberado | D32: à vontade | E32: todos os dias | G32: X | H32: X | I32: X | J32: X | M32: Bebida alcoólica | N32: Toranja / grapefruit | O32: Bebida alcoólica
A33: Refrigerante zero | B33: Bebidas | C33: Moderar | D33: 200 ml | E33: 1x/dia | F33: Sugestão gerada por IA — confirmar com nutricionista/cardiologista | H33: X | I33: X | J33: X | M33: Açúcar refinado | N33: Suco de toranja / grapefruit | O33: Açúcar refinado
A34: Café sem açúcar | B34: Bebidas | C34: Liberado | D34: 1 xícara | E34: 2x/dia | G34: X | I34: X | M34: Sal light / substituto de sal (cloreto de potássio) | N34: Açúcar refinado | O34: Sal light / substituto de sal (cloreto de potássio)
A35: Suco natural sem açúcar | B35: Bebidas | C35: Moderar | D35: 200 ml | E35: 3x/semana | F35: Preferir a fruta inteira, que tem mais fibra | G35: X | I35: X | N35: Doces industrializados
A36: Suco de toranja / grapefruit | B36: Bebidas | C36: Evitar | D36: - | E36: evitar | F36: Interage com o Ticagrelor (estudo mostrou quase o dobro do nível do remédio no sangue); a bula diz que não é esperado ser clinicamente relevante p/ a maioria, mas orienta evitar — mais seguro evitar, já que você toma 2 antiagregantes. Ver aba Fontes e Referências. | G36: X | I36: X
A37: Bebida alcoólica | B37: Bebidas | C37: Evitar | D37: - | E37: evitar | F37: Piora diretamente os triglicerídeos; soma-se ao risco de sangramento da Aspirina + Ticagrelor. | H37: X | J37: X
A38: Açúcar refinado | B38: Doces e Sobremesas | C38: Evitar | D38: - | E38: evitar | F38: Impacto direto nos triglicerídeos | G38: X | H38: X | I38: X | J38: X
A39: Doces industrializados | B39: Doces e Sobremesas | C39: Evitar | D39: - | E39: evitar | I39: X
A40: Chocolate amargo (70%+) | B40: Doces e Sobremesas | C40: Moderar | D40: 10 g | E40: 2x/semana | F40: Sugestão gerada por IA — confirmar com nutricionista/cardiologista | I40: X
...
